Workbook
Name datapoint0: 'CF Historical'!$D$13
Name datapoint0: 'CF Intergrated'!$D$13
Name datapoint0: 'FY''26 Statements'!$D$13
Name datapoint0: 'IS Historical'!$D$13
Name PctChange: _xlfn.LAMBDA(_xlpm.final,_xlpm.initial,(_xlpm.final-_xlpm.initial)/_xlpm.initial)

Sheet Cover
A1: COVER PAGE
A2: NASDAQ:TEAM
A3: Macquarie University Research Group
A4: MURG
D5: Scenario Switch | E5: Base Case
D7: Weight:
D8: DCF | E8: =IF(E9<=0,1,1-E9) -> 1
D9: VWAP | E9: 0
D10: Implied Share Price (USD$) | E10: =E8*'DCF FINAL'!J61+E9*AVERAGE('Comp. Multi & Imp. Val'!Y48:Z50) -> 107.76789
D12: Downside/Upside | E12: =(E10-E13)/E13 -> -0.39497607
D13: VWAP Share Price | E13: ='VWAP LIVE'!I5 -> 178.1217

Sheet DCF FINAL
B1: Atlassian DCF
B2: NASDAQ:TEAM | D2: =D12/D11 -> 0.1137598 | E2: =E12/E11 -> 0.1215141 | F2: =F12/F11 -> 0.14640431 | G2: =G12/G11 -> 0.16445348 | H2: =H12/H11 -> 0.16628195 | I2: =I12/I11 -> 0.15648426 | J2: =J12/J11 -> 0.13026809 | K2: =K12/K11 -> 0.158406 | ... P2: =P12/P11 -> 0.183406
C3: Gross Margin % | D3: =D13/D11 -> 0.8862402 | E3: =E13/E11 -> 0.8784859 | F3: =F13/F11 -> 0.85359569 | G3: =G13/G11 -> 0.83554652 | H3: =H13/H11 -> 0.83371805 | I3: =I13/I11 -> 0.84351574 | J3: =J13/J11 -> 0.86973191 | K3: =K13/K11 -> 0.841594 | ... P3: =P13/P11 -> 0.816594
C4: Opex/Revenue % | D4: =SUM(D14:D16)/D11 -> 0.82474431 | E4: =SUM(E14:E16)/E11 -> 0.79050869 | F4: =SUM(F14:F16)/F11 -> 0.87182835 | G4: =SUM(G14:G16)/G11 -> 0.91836724 | H4: =SUM(H14:H16)/H11 -> 0.84251422 | I4: =SUM(I14:I16)/I11 -> 0.85342005 | J4: =SUM(J14:J16)/J11 -> 0.84675323 | K4: =SUM(K14:K16)/K11 -> 0.81654138 | ... P4: =SUM(P14:P16)/P11 -> 0.65654138
D5: 43983 | E5: 44377 | F5: =EDATE(E5,12) -> 44742 | G5: =EDATE(F5,12) -> 45107 | H5: =EDATE(G5,12) -> 45473 | I5: =EDATE(H5,12) -> 45838 | J5: =EDATE(I5,12) -> 46203 | K5: =EDATE(J5,12) -> 46568 | L5: =EDATE(K5,12) -> 46934 | M5: =EDATE(L5,12) -> 47299 | ... P5: =EDATE(O5,12) -> 48395
B6: Currently Running | C6: =Cover!E5 -> Base Case | D6: Actuals | E6: Actuals | F6: Actuals | G6: Actuals | H6: Actuals | I6: Actuals | J6: Actuals | K6: Forecast | L6: Forecast | M6: Forecast | N6: Forecast | O6: Forecast | P6: Forecast | T6: H-Model DCF
K7: 1 | L7: 2 | M7: 3 | N7: 4 | O7: 5 | P7: 6 | T7: Source: Team 2 Atlassian DCF
T8: Inputs
T9: FCF Final Explicit Year, FY32 ($M) | U9: =P31 -> 2422.7727
E10: =E11/D11-1 -> 0.29424293 | F10: =F11/E11-1 -> 0.34164907 | G10: =G11/F11-1 -> 0.26107592 | H10: =H11/G11-1 -> 0.23310843 | I10: =I11/H11-1 -> 0.19655403 | J10: =J11/I11-1 -> 0.26019653 | K10: =K11/J11-1 -> 0.14729193 | L10: =L11/K11-1 -> 0.21108027 | ... P10: =P11/O11-1 -> 0.10145761 | T10: WACC | U10: =WACC!H55 -> 0.098174268
B11: Revenue | D11: ='IS Intergrated'!E10 -> 1614.173 | E11: ='IS Intergrated'!F10 -> 2089.132 | F11: ='IS Intergrated'!G10 -> 2802.882 | G11: ='IS Intergrated'!H10 -> 3534.647 | H11: ='IS Intergrated'!I10 -> 4358.603 | I11: ='IS Intergrated'!J10 -> 5215.304 | J11: ='IS Intergrated'!K10 -> 6572.308 | K11: ='IS Intergrated'!L10 -> 7540.3559 | ... P11: ='IS Intergrated'!Q10 -> 16156.084 | T11: g_S Exit growth rate (FY32) | U11: =P36 -> 0.10145761
B12: COGS (Excl. D&A) | D12: ='IS Intergrated'!E17 -> 183.628 | E12: ='IS Intergrated'!F17 -> 253.859 | F12: ='IS Intergrated'!G17 -> 410.354 | G12: ='IS Intergrated'!H17 -> 581.285 | H12: ='IS Intergrated'!I17 -> 724.757 | I12: ='IS Intergrated'!J17 -> 816.113 | J12: ='IS Intergrated'!K17 -> 856.162 | K12: ='IS Intergrated'!L17 -> 1194.4376 | ... P12: ='IS Intergrated'!Q17 -> 2963.1227 | T12: g_L Long-run perpetuity growth | U12: =J44 -> 0.035
B13: Gross Profit | D13: =D11-D12 -> 1430.545 | E13: =E11-E12 -> 1835.273 | F13: =F11-F12 -> 2392.528 | G13: =G11-G12 -> 2953.362 | H13: =H11-H12 -> 3633.846 | I13: =I11-I12 -> 4399.191 | J13: =J11-J12 -> 5716.146 | K13: =K11-K12 -> 6345.9183 | ... P13: =P11-P12 -> 13192.961 | T13: Fade Period (Years) | U13: 8
B14: R&D Expense | D14: ='IS Intergrated'!E25 -> 763.188 | E14: ='IS Intergrated'!F25 -> 963.326 | F14: ='IS Intergrated'!G25 -> 1397.568 | G14: ='IS Intergrated'!H25 -> 1869.881 | H14: ='IS Intergrated'!I25 -> 2184.111 | I14: ='IS Intergrated'!J25 -> 2669.312 | J14: ='IS Intergrated'!K25 -> 3269.257 | K14: ='IS Intergrated'!L25 -> 3488.1887 | ... P14: ='IS Intergrated'!Q25 -> 5454.3368 | T14: H (Fade Period / 2) | U14: =U13/2 -> 4
B15: M&S Expense | D15: ='IS Intergrated'!E26 -> 299.683 | E15: ='IS Intergrated'!F26 -> 372.909 | F15: ='IS Intergrated'!G26 -> 567.691 | G15: ='IS Intergrated'!H26 -> 769.861 | H15: ='IS Intergrated'!I26 -> 877.497 | I15: ='IS Intergrated'!J26 -> 1134.535 | J15: ='IS Intergrated'!K26 -> 1541.178 | K15: ='IS Intergrated'!L26 -> 1768.1811 | ... P15: ='IS Intergrated'!Q26 -> 3626.9714
B16: G&A Expense | D16: ='IS Intergrated'!E27 -> 268.409 | E16: ='IS Intergrated'!F27 -> 315.242 | F16: ='IS Intergrated'!G27 -> 478.373 | G16: ='IS Intergrated'!H27 -> 606.362 | H16: ='IS Intergrated'!I27 -> 610.577 | I16: ='IS Intergrated'!J27 -> 646.998 | J16: ='IS Intergrated'!K27 -> 754.688 | K16: ='IS Intergrated'!L27 -> 900.64289 | ... P16: ='IS Intergrated'!Q27 -> 1525.8293 | T16: Terminal Value H-Model EOFY '32/ Year 6
B17: EBITDA | D17: =D13-SUM(D14:D16) -> 99.265 | E17: =E13-SUM(E14:E16) -> 183.796 | F17: =F13-SUM(F14:F16) -> -51.104 | G17: =G13-SUM(G14:G16) -> -292.742 | H17: =H13-SUM(H14:H16) -> -38.339 | I17: =I13-SUM(I14:I16) -> -51.654 | J17: =J13-SUM(J14:J16) -> 151.023 | K17: =K13-SUM(K14:K16) -> 188.90568 | ... P17: =P13-SUM(P14:P16) -> 2585.8235 | T17: Gordon component = FCF * (1+g_L)/(WACC-g_L) | U17: =U9*(1+U12)/(U10-U12) -> 39692.897
B18: D&A | D18: ='IS Intergrated'!E18 -> 85.179 | E18: ='IS Intergrated'!F18 -> 82.162 | F18: ='IS Intergrated'!G18 -> 55.353 | G18: ='IS Intergrated'!H18 -> 52.48 | H18: ='IS Intergrated'!I18 -> 78.738 | I18: ='IS Intergrated'!J18 -> 78.738 | J18: ='IS Intergrated'!K18 -> 140.67 | K18: ='IS Intergrated'!L18 -> 139.14995 | ... P18: ='IS Intergrated'!Q18 -> 80.690798 | T18: Fade Premium: FCF * H*(g_S-g_L)/(WACC-g_L) | U18: =U9*U14*(U11-U12)/(U10-U12) -> 10194.763
B19: EBIT | D19: =D17-D18 -> 14.086 | E19: =E17-E18 -> 101.634 | F19: =F17-F18 -> -106.457 | G19: =G17-G18 -> -345.222 | H19: =H17-H18 -> -117.077 | I19: =I17-I18 -> -130.392 | J19: =J17-J18 -> 10.353 | K19: =K17-K18 -> 49.755724 | ... P19: =P17-P18 -> 2505.1327 | T19: Terminal Value (H-Model) | U19: =SUM(U17+U18) -> 49887.66
B20: Non-Operating Income | D20: ='IS Intergrated'!E31+'IS Intergrated'!E39 -> -360.295 | E20: ='IS Intergrated'!F31+'IS Intergrated'!F39 -> -736.298 | F20: ='IS Intergrated'!G31+'IS Intergrated'!G39 -> -458.085 | G20: ='IS Intergrated'!H31+'IS Intergrated'!H39 -> 34.086 | H20: ='IS Intergrated'!I31+'IS Intergrated'!I39 -> 31.67 | I20: ='IS Intergrated'!J31+'IS Intergrated'!J39 -> 31.497 | J20: ='IS Intergrated'!K31 -> 11.695 | K20: ='IS Intergrated'!L31 -> 12.104538 | L20: ='IS Intergrated'!M31 -> 22.941378 | M20: ='IS Intergrated'!N31 -> 35.760401 | N20: ='IS Intergrated'!O31 -> 57.610478 | O20: ='IS Intergrated'!P31 -> 88.971914 | P20: ='IS Intergrated'!Q31 -> 132.86386 | T20: PV of Terminal Value = TV/(1+WACC)^6 | U20: =U19/(1+U10)^P7 -> 28442.355
B21: Taxes | D21: ='IS Intergrated'!E38 -> 4.445 | E21: ='IS Intergrated'!F38 -> 61.651 | F21: ='IS Intergrated'!G38 -> 49.582 | G21: ='IS Intergrated'!H38 -> 175.625 | H21: ='IS Intergrated'!I38 -> 215.112 | I21: ='IS Intergrated'!J38 -> 157.792 | J21: ='IS Intergrated'!K38 -> 75.878 | K21: ='IS Intergrated'!L38 -> 14.846463 | ... P21: ='IS Intergrated'!Q38 -> 633.11919 | T21: Cross-Check (Reg. GGM)
B22: Net Income | D22: =D19+D20-D21 -> -350.654 | E22: =E19+E20-E21 -> -696.315 | F22: =F19+F20-F21 -> -614.124 | G22: =G19+G20-G21 -> -486.761 | H22: =H19+H20-H21 -> -300.519 | I22: =I19+I20-I21 -> -256.687 | J22: =J19+J20-J21 -> -53.83 | K22: =K19+K20-K21 -> 47.013799 | ... P22: =P19+P20-P21 -> 2004.8774 | T22: Terminal Value (Gordon) = FCF * (1+g_L)(WACC-g_L) | U22: =U9*(1+J44)/(U10-U12) -> 39692.897
T23: H-Model Premium vs. Gordon (%) | U23: =U19/U22-1 -> 0.25684099
B24: (+) D&A | D24: =D18 -> 85.179 | E24: =E18 -> 82.162 | F24: =F18 -> 55.353 | G24: =G18 -> 52.48 | H24: =H18 -> 78.738 | I24: =I18 -> 78.738 | J24: =J18 -> 140.67 | K24: =K18 -> 139.14995 | ... P24: =P18 -> 80.690798
B25: (-) CapEx | D25: ='CF Intergrated'!E30 -> -35.709 | E25: ='CF Intergrated'!F30 -> -33.32 | F25: ='CF Intergrated'!G30 -> -74.601 | G25: ='CF Intergrated'!H30 -> -25.812 | H25: ='CF Intergrated'!I30 -> -33.112 | I25: ='CF Intergrated'!J30 -> -44.85 | J25: ='CF Intergrated'!K30 -> -34.06 | K25: ='CF Intergrated'!L30 -> -58.709653 | ... P25: ='CF Intergrated'!Q30 -> -59.486081
B26: (-) Change in NWC | D26: ='CF Intergrated'!E18 -> 143.019 | E26: ='CF Intergrated'!F18 -> 233.502 | F26: ='CF Intergrated'!G18 -> 253.237 | G26: ='CF Intergrated'!H18 -> 308.556 | H26: ='CF Intergrated'!I18 -> 576.989 | I26: ='CF Intergrated'!J18 -> 264.809 | J26: ='CF Intergrated'!K18 -> -375.999 | K26: ='CF Intergrated'!L18 -> 413.03206 | ... P26: ='CF Intergrated'!Q18 -> 437.97892 | T26: H-Model Share Price
B27: (+) Int Exp | D27: ='IS Intergrated'!E34*(1-'DCS Detail'!$D$57) -> -37.7036 | E27: ='IS Intergrated'!F34*(1-'DCS Detail'!$D$57) -> -93.26188 | F27: ='IS Intergrated'!G34*(1-'DCS Detail'!$D$57) -> -19.62624 | G27: ='IS Intergrated'!H34*(1-'DCS Detail'!$D$57) -> -22.91172 | H27: ='IS Intergrated'!I34*(1-'DCS Detail'!$D$57) -> -25.89852 | I27: ='IS Intergrated'!J34*(1-'DCS Detail'!$D$57) -> -23.218 | J27: ='IS Intergrated'!K34*(1-'DCS Detail'!$D$57) -> -37.582 | K27: ='IS Intergrated'!L34*(1-'DCS Detail'!$D$57) -> -41.288401 | ... P27: ='IS Intergrated'!Q34*(1-'DCS Detail'!$D$57) -> -41.288401 | T27: H-Model Terminal Value | W27: =U19 -> 49887.66
B28: (+) Stock Based Compensation | D28: ='SBC Ratios'!E6 -> 313.395 | E28: ='SBC Ratios'!F6 -> 385.732 | F28: ='SBC Ratios'!G6 -> 707.087 | G28: ='SBC Ratios'!H6 -> 948.087 | H28: ='SBC Ratios'!I6 -> 1081.433 | I28: ='SBC Ratios'!J6 -> 1362.222 | J28: ='SBC Ratios'!K6 -> 1606.561 | K28: ='CF Intergrated'!L14 -> 1780.6478 | L28: ='CF Intergrated'!M14 -> 2110.8476 | M28: ='CF Intergrated'!N14 -> 2491.149 | N28: ='CF Intergrated'!O14 -> 2869.8171 | O28: ='CF Intergrated'!P14 -> 3170.4552 | P28: ='CF Intergrated'!Q14 -> 3411.3416 | Q28: NON LIVE | T28: PV terminal value | W28: =W27/(1+U10)^P7 -> 28442.355
B29: (-) Adjustment For SBC | D29: =-(1-'Chaffe-Finnerty DLOM'!$J$14)*'DCF FINAL'!D28 -> -231.29476 | E29: =-(1-'Chaffe-Finnerty DLOM'!$J$14)*'DCF FINAL'!E28 -> -284.68159 | F29: =-(1-'Chaffe-Finnerty DLOM'!$J$14)*'DCF FINAL'!F28 -> -521.85106 | G29: =-(1-'Chaffe-Finnerty DLOM'!$J$14)*'DCF FINAL'!G28 -> -699.71617 | H29: =-(1-'Chaffe-Finnerty DLOM'!$J$14)*'DCF FINAL'!H28 -> -798.12946 | I29: =-(1-'Chaffe-Finnerty DLOM'!$J$14)*'DCF FINAL'!I28 -> -1005.36 | J29: =-(1-'Chaffe-Finnerty DLOM'!$J$14)*'DCF FINAL'!J28 -> -1185.6894 | K29: =-(1-'Chaffe-Finnerty DLOM'!$J$14)*'DCF FINAL'!K28 -> -1314.1706 | ... P29: =-(1-'Chaffe-Finnerty DLOM'!$J$14)*'DCF FINAL'!P28 -> -2517.6707 | Q29: NON LIVE | T29: PV FCF (JUN '27 to JUN '32) | W29: =SUM(K32:P32) -> 5400.2587
T30: Enterprise value | W30: =W28+W29 -> 33842.614
B31: Total FCF | D31: =SUM(D22:D27) -> -195.8686 | E31: =SUM(E22:E27) -> -507.23288 | F31: =SUM(F22:F27) -> -399.76124 | G31: =SUM(G22:G27) -> -174.44872 | H31: =SUM(H22:H27) -> 296.19748 | I31: =SUM(I22:I27) -> 18.792 | J31: =SUM(J22:J27) -> -360.801 | K31: =SUM(K22:K27) -> 499.19776 | ... P31: =SUM(P22:P27) -> 2422.7727 | T31: Cash | W31: ='BS Intergrated'!K11 -> 1239.512
B32: (PV) FCF | K32: =K31/(1+$J$43)^K7 -> 454.57062 | L32: =L31/(1+$J$43)^L7 -> 612.67767 | M32: =M31/(1+$J$43)^M7 -> 765.30508 | N32: =N31/(1+$J$43)^N7 -> 1004.276 | O32: =O31/(1+$J$43)^O7 -> 1182.1386 | P32: =P31/(1+$J$43)^P7 -> 1381.2907 | T32: Debt | W32: =J57 -> 1232.91
T33: Net debt | W33: =W32-W31 -> -6.602
B34: FCF Margin (%) | D34: =D31/D11 -> -0.121343 | E34: =E31/E11 -> -0.24279599 | F34: =F31/F11 -> -0.14262507 | G34: =G31/G11 -> -0.04935393 | H34: =H31/H11 -> 0.067956976 | I34: =I31/I11 -> 0.0036032415 | J34: =J31/J11 -> -0.054897153 | K34: =K31/K11 -> 0.066203474 | ... P34: =P31/P11 -> 0.14996039 | T34: Equity Value | W34: =W30+W31-W32 -> 33849.216
B35: FCF Margin (5dp) | D35: =D34 -> -0.121343 | E35: =E34 -> -0.24279599 | F35: =F34 -> -0.14262507 | G35: =G34 -> -0.04935393 | H35: =H34 -> 0.067956976 | I35: =I34 -> 0.0036032415 | J35: =J34 -> -0.054897153 | K35: =K34 -> 0.066203474 | ... P35: =P34 -> 0.14996039
B36: Sales Growth (5dp) | E36: =E11/D11-1 -> 0.29424293 | F36: =F11/E11-1 -> 0.34164907 | G36: =G11/F11-1 -> 0.26107592 | H36: =H11/G11-1 -> 0.23310843 | I36: =I11/H11-1 -> 0.19655403 | J36: =J11/I11-1 -> 0.26019653 | K36: =K11/J11-1 -> 0.14729193 | L36: =L11/K11-1 -> 0.21108027 | ... P36: =P11/O11-1 -> 0.10145761 | T36: No. Diluted Shares (M) | W36: ='Comp. Multi & Imp. Val'!W13 -> 260.16
B37: Net Income Margin (%) | D37: =D22/D11 -> -0.21723446 | E37: =E22/E11 -> -0.3333035 | F37: =F22/F11 -> -0.21910448 | G37: =G22/G11 -> -0.13771135 | H37: =H22/H11 -> -0.068948468 | I37: =I22/I11 -> -0.049218032 | J37: =J22/J11 -> -0.0081904256 | K37: =K22/K11 -> 0.0062349576 | ... P37: =P22/P11 -> 0.12409427
B38: PV SBC | K38: =(K28+K29)/((1+$J$43)^K7) -> 424.77521 | L38: =(L28+L29)/((1+$J$43)^L7) -> 458.52892 | M38: =(M28+M29)/((1+$J$43)^M7) -> 492.76325 | N38: =(N28+N29)/((1+$J$43)^N7) -> 516.91788 | O38: =(O28+O29)/((1+$J$43)^O7) -> 520.01719 | P38: =(P28+P29)/((1+$J$43)^P7) -> 509.50684 | T38: Estimated Share Price (DCF) - H-Model | W38: =W34/W36 -> 130.10922
T39: Upside/(Discount) to Valuation | W39: =W38/W40-1 -> -0.26954874
T40: VWAP Share Price | W40: ='VWAP LIVE'!I5 -> 178.1217
...

Sheet Comp. Multi & Imp. Val
A1: Atlassian Comp. Multiples | V1: Implied Valuation - Trading Comparables (6 True Peers)
A2: NASDAQ: TEAM | H2: =H15/G15 -> 0.26742591 | V2: Peer Set: ServiceNow, HubSpot, GitLab, Monday.com, Freshworks, Asana. Atlassian and Microsoft excluded from peer statistics.
A3: #VALUE! | H3: =H16/G16 -> 0.34041542 | AS3: X suffix | AT3: 0.00"x";(0.00"x")
A4: #VALUE! | H4: =H17/G17 -> 0.21108888 | V4: Atlassian Target Metrics | AS4: 2DP | AT4: #,##0.00;(#,##0.00)
A5: #VALUE! | H5: =H18/G18 -> 0.15356752 | V5: NTM Sales ($M) | W5: =M15 -> 7540.3559 | AS5: Percentages | AT5: 0.0%;(0.0%)
A6: #VALUE! | H6: =H19/G19 -> 0.16955949 | V6: NTM Adj. EBITDA ($M) | W6: =N15 -> 1969.5535
A7: #VALUE! | H7: =H20/G20 -> 0.18837261 | V7: LTM FCF ($M) | W7: =K15 -> 1319.069
A8: #VALUE! | H8: =H21/G21 -> 0.058669305 | V8: TEV ($M) | W8: =E15 -> 46333.541
A9: #VALUE! | V9: Market Cap ($M) | W9: =D15 -> 46340.143
A10: #VALUE! | V10: Share Price ($/share) | W10: =C15 -> 178.1217
A11: Comparable Multiples
C12: Market Data | G12: Financial Data (LTM)1 | M12: Financial Data (NTM) | P12: Metrics | V12: Net Debt = TEV - Market Cap ($M) | W12: =E15-D15 -> -6.602
C13: Price | D13: Fully Diluted Market Cap | E13: TEV | G13: Sales | H13: Adjusted EBITDA 2 | I13: EBIT | J13: Earnings | K13: FCF | M13: Sales (NTM) | N13: Adjusted EBITDA (NTM)2 | P13: EV/Revenue (NTM) | Q13: EV/EBITDA (NTM) | R13: Revenue Growth (LTM, implied) | S13: Rule of 40 | T13: EV/FCF (LTM) | V13: Diluted Shares (Market Cap ÷ Price, M) | W13: =W9/W10 -> 260.16
A14: Company Name | B14: Market Category | C14: ($/share) | D14: ($M) | E14: ($M) | G14: ($M) | H14: ($M) | I14: ($M) | J14: ($M) | K14: ($M) | M14: ($M) | N14: ($M) | P14: X | Q14: X | R14: (%) | S14: (%) | T14: X
A15: Atlassian Corp | B15: Enterprise Software | C15: ='VWAP LIVE'!I5 -> 178.1217 | D15: =C15*260.16 -> 46340.143 | E15: =D15+('BS Historical Updated'!J47+'BS Historical Updated'!J54+'BS Historical Updated'!J55)-'BS Historical Updated'!J7 -> 46333.541 | G15: 6572.31 | H15: ='IS Historical'!K52+K32 -> 1757.606 | I15: ='IS Historical'!K28 -> 10.353 | J15: -53.8 | K15: ='CF Intergrated'!K53 -> 1319.069 | M15: ='IS Intergrated'!L10 -> 7540.3559 | N15: ='IS Intergrated'!L55+'CF Assumptions'!F38 -> 1969.5535 | P15: =E15/M15 -> 6.1447418 | Q15: =E15/N15 -> 23.524896 | R15: =(G15/'IS Intergrated'!J10)-1 -> 0.26019691 | S15: =R15+K15/G15 -> 0.46089788 | T15: =E15/K15 -> 35.125942 | V15: Method 1: EV/Revenue (NTM) - Implied Valuation
A16: ServiceNow | B16: IT Service Management | C16: {=_FV(A4,"Price")} -> 142.35 | D16: =C16*1034.33 -> 147236.88 | E16: =D16-6290+1491 -> 142437.88 | G16: 14732 | H16: =2983+K33 -> 5015 | I16: 2001 | J16: 1670 | K16: 4580 | M16: =0.5*16209+0.5*19245 -> 17727 | N16: =0.5*6323+0.5*7554 -> 6938.5 | P16: =E16/M16 -> 8.0350807 | Q16: =E16/N16 -> 20.528627 | R16: =(M16/G16)-1 -> 0.20329894 | S16: =R16+K16/G16 -> 0.5141868 | T16: =E16/K16 -> 31.099973 | V16: Statisitic | W16: Peer Mutliple | X16: Target Metric | Y16: Implied EV | Z16: (-) Net Debt | AA16: Implied Equity Value | AB16: Implied Share Price
A17: HubSpot | B17: Customer Relationship Management | C17: {=_FV(A5,"Price")} -> 250.61 | D17: =C17*51.34 -> 12866.317 | E17: =10027.88-1337.94-119.46 -> 8570.48 | G17: 3448.5 | H17: =321.34+K38 -> 727.94 | I17: 134.23 | J17: 146.9 | K17: 694.88 | M17: =0.5*3683+0.5*4204 -> 3943.5 | N17: =0.5*922+0.5*1113 -> 1017.5 | P17: =E17/M17 -> 2.1733181 | Q17: =E17/N17 -> 8.4230762 | R17: =(M17/G17)-1 -> 0.14354067 | S17: =R17+K17/G17 -> 0.34504277 | T17: =E17/K17 -> 12.333755
A18: GitLab | B18: Development & Security Operations | C18: {=_FV(A6,"Price")} -> 49.25 | D18: =C18*184.51 -> 9087.1175 | E18: =D18-1357.51+46.18 -> 7775.7875 | G18: 1004.9 | H18: =-32.98+K34 -> 154.32 | I18: -45.06 | J18: -25.1 | K18: 263.44 | M18: =((0.5)*1117)+((0.5)*1286) -> 1201.5 | N18: =((10/12)*145)+((2/12)*184) -> 151.5 | P18: =E18/M18 -> 6.4717333 | Q18: =E18/N18 -> 51.32533 | R18: =(M18/G18)-1 -> 0.19564136 | S18: =R18+K18/G18 -> 0.4577968 | T18: =E18/K18 -> 29.516351 | V18: Low | W18: =MIN($P16:$P21) -> 1.8793972 | X18: =W5 -> 7540.3559 | Y18: =W18*X18 -> 14171.324 | Z18: =$W$12 -> -6.602 | AA18: =Y18+Z18 -> 14164.722 | AB18: =AA18/$W$13 -> 54.446195
A19: Monday.com | B19: Project Management | C19: {=_FV(A7,"Price")} -> 96.105 | D19: =C19*43.97 -> 4225.7369 | E19: =D19+0-1212.28 -> 3013.4569 | G19: 1366.6 | H19: =54.71+K35 -> 231.72 | I19: 39.65 | J19: 121.24 | K19: 318.2 | M19: =((5/12)*1471)+((7/12)*1698) -> 1603.4167 | N19: =((5/12)*234)+((7/12)*296) -> 270.16667 | P19: =E19/M19 -> 1.8793972 | Q19: =E19/N19 -> 11.154066 | R19: =(M19/G19)-1 -> 0.17328894 | S19: =R19+K19/G19 -> 0.40612957 | T19: =E19/K19 -> 9.4703232 | V19: 25th Percentile | W19: =_xlfn.QUARTILE.INC(P16:P21,1) -> 2.1962557 | X19: =W5 -> 7540.3559 | Y19: =W19*X19 -> 16560.55 | Z19: =$W$12 -> -6.602 | AA19: =Y19+Z19 -> 16553.948 | AB19: =AA19/$W$13 -> 63.629874 | AE19: =P13 -> EV/Revenue (NTM) | AF19: =Q13 -> EV/EBITDA (NTM) | AG19: =T13 -> EV/FCF (LTM)
A20: Freshworks | B20: IT Service Management | C20: {=_FV(A8,"Price")} -> 12.64 | D20: =C20*292.11 -> 3692.2704 | E20: =D20+13-665.26 -> 3040.0104 | G20: 903.9 | H20: =68.17+K39 -> 170.27 | I20: 37.31 | J20: 185.19 | K20: 220.56 | M20: =((10/12)*965+(2/12)*1102) -> 987.83333 | N20: =((10/12)*250.2+(2/12)*292.2) -> 257.2 | P20: =E20/M20 -> 3.0774527 | Q20: =E20/N20 -> 11.819636 | R20: =(M20/G20)-1 -> 0.092856879 | S20: =R20+K20/G20 -> 0.33686617 | T20: =E20/K20 -> 13.783145 | V20: Median | W20: =MEDIAN(P16:P21) -> 2.6712607 | X20: =W5 -> 7540.3559 | Y20: =W20*X20 -> 20142.256 | Z20: =$W$12 -> -6.602 | AA20: =Y20+Z20 -> 20135.654 | AB20: =AA20/$W$13 -> 77.397194 | AD20: Peers (Average) | AE20: =P22 -> 3.9836751 | AF20: =Q22 -> 20.172586 | AG20: =T22 -> 19.101425
A21: Asana | B21: Project Management | C21: {=_FV(A9,"Price")} -> 9.66 | D21: =C21*244.58 -> 2362.6428 | E21: =D21-425.35+38.3 -> 1975.5928 | G21: 808.6 | H21: =-112.93+K36 -> 47.44 | I21: -136.05 | J21: -163.41 | K21: 107.34 | M21: =((10/12)*860.8)+((2/12)*929.2) -> 872.2 | N21: =((10/12)*106.6)+((2/12)*133.5) -> 111.08333 | P21: =E21/M21 -> 2.2650686 | Q21: =E21/N21 -> 17.784781 | R21: =(M21/G21)-1 -> 0.078654465 | S21: =R21+K21/G21 -> 0.21140242 | T21: =E21/K21 -> 18.405001 | V21: Mean | W21: =AVERAGE(P16:P21) -> 3.9836751 | X21: =W5 -> 7540.3559 | Y21: =W21*X21 -> 30038.328 | Z21: =$W$12 -> -6.602 | AA21: =Y21+Z21 -> 30031.726 | AB21: =AA21/$W$13 -> 115.4356 | AD21: Atlassian | AE21: =P15 -> 6.1447418 | AF21: =Q15 -> 23.524896 | AG21: =T15 -> 35.125942
A22: Average (peers only) | C22: =AVERAGE(C16:C21) -> 93.435833 | D22: =AVERAGE(D16:D21) -> 29911.827 | E22: =AVERAGE(E16:E21) -> 27802.201 | G22: =AVERAGE(G16:G21) -> 3710.75 | H22: =AVERAGE(H16:H21) -> 1057.7817 | I22: =AVERAGE(I16:I21) -> 338.51333 | J22: =AVERAGE(J16:J21) -> 322.47 | K22: =AVERAGE(K16:K21) -> 1030.7367 | M22: =AVERAGE(M16:M21) -> 4389.2417 | N22: =AVERAGE(N16:N21) -> 1457.6583 | P22: =AVERAGE(P16:P21) -> 3.9836751 | Q22: =AVERAGE(Q16:Q21) -> 20.172586 | R22: =AVERAGE(R16:R21) -> 0.14788021 | S22: =AVERAGE(S16:S21) -> 0.37857076 | T22: =AVERAGE(T16:T21) -> 19.101425 | V22: 75th Percentile | W22: =_xlfn.QUARTILE.INC(P16:P21,3) -> 5.6231631 | X22: =W5 -> 7540.3559 | Y22: =W22*X22 -> 42400.651 | Z22: =$W$12 -> -6.602 | AA22: =Y22+Z22 -> 42394.049 | AB22: =AA22/$W$13 -> 162.95376
A23: Median (peers only) | C23: =MEDIAN(C16:C21) -> 72.6775 | D23: =MEDIAN(D16:D21) -> 6656.4272 | E23: =MEDIAN(E16:E21) -> 5407.899 | G23: =MEDIAN(G16:G21) -> 1185.75 | H23: =MEDIAN(H16:H21) -> 200.995 | I23: =MEDIAN(I16:I21) -> 38.48 | J23: =MEDIAN(J16:J21) -> 134.07 | K23: =MEDIAN(K16:K21) -> 290.82 | M23: =MEDIAN(M16:M21) -> 1402.4583 | N23: =MEDIAN(N16:N21) -> 263.68333 | P23: =MEDIAN(P16:P21) -> 2.6712607 | Q23: =MEDIAN(Q16:Q21) -> 14.802209 | R23: =MEDIAN(R16:R21) -> 0.15841481 | S23: =MEDIAN(S16:S21) -> 0.37558617 | T23: =MEDIAN(T16:T21) -> 16.094073 | V23: High | W23: =MAX(P16:P21) -> 8.0350807 | X23: =W5 -> 7540.3559 | Y23: =W23*X23 -> 60587.368 | Z23: =$W$12 -> -6.602 | AA23: =Y23+Z23 -> 60580.766 | AB23: =AA23/$W$13 -> 232.85965
A24: Microsoft4 | B24: Diversified Enterprise Software | C24: {=_FV(A10,"Price")} -> 505.41 | D24: =C24*7503.55 -> 3792369.2 | E24: =D24+40294-(76843+27240) -> 3728580.2 | G24: =331.84*1000 -> 331840 | H24: =(198.69*1000)+K37 -> 211095 | I24: =155.24*1000 -> 155240 | J24: =133.75*1000 -> 133750 | K24: =66.92*1000 -> 66920 | M24: 390396 | N24: 242166 | P24: =E24/M24 -> 9.5507644 | Q24: =E24/N24 -> 15.396795 | R24: =(M24/G24)-1 -> 0.17645853 | S24: =R24+K24/G24 -> 0.37812199 | T24: =E24/K24 -> 55.716979
A25: 1Financial data as of March 31, 2026 (GitLab reflects LTM/NTM through April 30, 2026 per fiscal reporting calendar) | V25: Method 2: EV/EBITDA (NTM) - Implied Valuation
A26: 2EBITDA is presented on an adjusted basis throughout: LTM figures represent GAAP EBITDA plus stock-based compensation (self-calculated via financial statements); NTM figures reflect non-GAAP consensus estimates. This approach ensures consistency across the peer set given inconsistent GAAP estimates | V26: Statisitic | W26: Peer Mutliple | X26: Target Metric | Y26: Implied EV | Z26: (-) Net Debt | AA26: Implied Equity Value | AB26: Implied Share Price
A27: P/E is excluded as Atlassian and several peers report negative LTM net income
A28: 4Microsoft is included as a reference, excluded from average/median due to scale mismatch | V28: Low | W28: =MIN(Q16:Q21) -> 8.4230762 | X28: =$N$15 -> 1969.5535 | Y28: =W28*X28 -> 16589.699 | Z28: =Z18 -> -6.602 | AA28: =Y28+Z28 -> 16583.097 | AB28: =AA28/$W$13 -> 63.741917
A29: Source: Factset, Team Analysis | V29: 25th Percentile | W29: =_xlfn.QUARTILE.INC(Q16:Q21,1) -> 11.320459 | X29: =$N$15 -> 1969.5535 | Y29: =W29*X29 -> 22296.249 | Z29: =Z19 -> -6.602 | AA29: =Y29+Z29 -> 22289.647 | AB29: =AA29/$W$13 -> 85.676687
V30: Median | W30: =MEDIAN(Q16:Q21) -> 14.802209 | X30: =$N$15 -> 1969.5535 | Y30: =W30*X30 -> 29153.742 | Z30: =Z20 -> -6.602 | AA30: =Y30+Z30 -> 29147.14 | AB30: =AA30/$W$13 -> 112.03544
J31: Rolling LTM SBC | V31: Mean | W31: =AVERAGE(Q16:Q21) -> 20.172586 | X31: =$N$15 -> 1969.5535 | Y31: =W31*X31 -> 39730.988 | Z31: =Z21 -> -6.602 | AA31: =Y31+Z31 -> 39724.386 | AB31: =AA31/$W$13 -> 152.69213
A32: Metric | C32: Measurement | J32: Atlassian Corp | K32: 1606.561 | V32: 75th Percentile | W32: =_xlfn.QUARTILE.INC(Q16:Q21,3) -> 19.842665 | X32: =$N$15 -> 1969.5535 | Y32: =W32*X32 -> 39081.191 | Z32: =Z22 -> -6.602 | AA32: =Y32+Z32 -> 39074.589 | AB32: =AA32/$W$13 -> 150.19445
A33: EV/Rev (NTM) | C33: Measures market valuation of Atlassian's top-line sales (independent of profitability) | J33: ServiceNow | K33: =1955+547-470 -> 2032 | V33: High | W33: =MAX(Q16:Q21) -> 51.32533 | X33: =$N$15 -> 1969.5535 | Y33: =W33*X33 -> 101087.98 | Z33: =Z23 -> -6.602 | AA33: =Y33+Z33 -> 101081.38 | AB33: =AA33/$W$13 -> 388.53545
A34: =Q13 -> EV/EBITDA (NTM) | C34: Determines whether a company is undervalued/overvalued by comparing its total business value to its core cash earnings | J34: GitLab | K34: =50.1+53.2+41.1+42.9 -> 187.3
A35: =R13 -> Revenue Growth (LTM, implied) | C35: Increase in company's YoY sales | J35: Monday.com | K35: 177.01 | V35: Method 3: EV/FCF (LTM) - Implied Valuation
A36: Rule of 40 (EBITDA) | C36: SaaS industry multiple that states a company's annual revenue growth rate and its profit margin should total 40% or more | J36: Asana | K36: 160.37 | V36: Statisitic | W36: Peer Mutliple | X36: Target Metric | Y36: Implied EV | Z36: (-) Net Debt | AA36: Implied Equity Value | AB36: Implied Share Price
A37: =T13 -> EV/FCF (LTM) | C37: Measures how many dollars of company valuation you pay for each dollar generated | J37: MSFT | K37: 12405
J38: HubSpot | K38: 406.6 | V38: Low | W38: =MIN(T16:T21) -> 9.4703232 | X38: =$W$7 -> 1319.069 | Y38: =W38*X38 -> 12492.01 | Z38: =Z28 -> -6.602 | AA38: =Y38+Z38 -> 12485.408 | AB38: =AA38/$W$13 -> 47.991266
J39: Freshworks | K39: 102.1 | V39: 25th Percentile | W39: =_xlfn.QUARTILE.INC(T16:T21,1) -> 12.696103 | X39: =$W$7 -> 1319.069 | Y39: =W39*X39 -> 16747.036 | Z39: =Z29 -> -6.602 | AA39: =Y39+Z39 -> 16740.434 | AB39: =AA39/$W$13 -> 64.346685
V40: Median | W40: =T23 -> 16.094073 | X40: =$W$7 -> 1319.069 | Y40: =W40*X40 -> 21229.193 | Z40: =Z30 -> -6.602 | AA40: =Y40+Z40 -> 21222.591 | AB40: =AA40/$W$13 -> 81.575148
...

Sheet Monte Carlo, VaR &CVaR
A1: Updated 5/08/2026
B2: Atlassian (TEAM) - DCF Monte Carlo Simulation Results | I2: Monte Carlo Python Data
B3: Implied Share Price Distribution - 50,000 Simulations | I3: Variable | J3: Distribution | L3: Standard Deviation | M3: Justification
I4: Sales Growth (YoY) | J4: Normal, centered on detrended sales growth (2016 to 2026) | L4: 0.041041 | M4: FCF driver
B5: Percentile (%) | D5: Implied Share Price (USD$) | F5: Interpretation | I5: FCF Margin | J5: Normal, centered on FCF/sales ratio (2023 to 2026) | L5: 0.056499 | M5: CAPEX/WC/NI uncertainty
I6: WACC | J6: Normal, centered at 9.49% | L6: ='WACC FF Data'!B26*WACC!H19 -> 0.020873254 | M6: Discount rate risk
B7: 5th Percentile | D7: 35.49 | F7: Bearish tail - only 5% of outcomes fall below | I7: Long-run growth rate (g_L) | J7: Normal, centered at 3.5% (1986 to 2026) | L7: 0.010689 | M7: Terminal value sensitivity
B8: 10th Percentile | D8: 44.25
B9: 25th Percentile | D9: 64.45
B10: 50th Percentile | D10: 99.31 | F10: Median - Central Estimate
B11: Mean | D11: 125.01 | F11: Simulation Average
B12: 75th Percentile | D12: 155.35
B13: 90th Percentile | D13: 233.8
B14: 95th Percentile | D14: 302.2 | F14: Bullish tail - only 5% of outcomes exceed above
B15: Current Share Price: | F15: ='VWAP LIVE'!I5 -> 178.1217 | I15: 529.5 | J15: 748.4 | K15: 1024.3 | L15: 1397 | M15: 1768 | N15: 2124 | O15: 2543 | P15: 2960 | Q15: 3261
I16: 2608 | J16: 2460 | K16: 4519 | L16: 5896 | M16: 7245 | N16: 8971 | O16: 10984 | P16: 13278 | Q16: 14732
E17: ="90% Confidence Range: "&TEXT(D7,"$#,##0.00")&" - "&TEXT(D14,"$#,##0.00") -> 90% Confidence Range: $35.49 - $302.20 | I17: =I15/I16 -> 0.20302914 | J17: =J15/J16 -> 0.30422764 | K17: =K15/K16 -> 0.22666519 | L17: =L15/L16 -> 0.2369403 | M17: =M15/M16 -> 0.24403037 | N17: =N15/N16 -> 0.2367629 | O17: =O15/O16 -> 0.23151857 | P17: =P15/P16 -> 0.22292514 | Q17: =Q15/Q16 -> 0.22135487
I19: 78.1 | J19: 161.1 | K19: 308.2 | L19: 519 | M19: 729.7 | N19: 972 | O19: 1232 | P19: 1366.6
I20: 24.6 | J20: 43.5 | K20: 73.7 | L20: 127 | M20: 156.5 | N20: 213.7 | O20: 320.8 | P20: 355.7
I21: =I20/I19 -> 0.31498079 | J21: =J20/J19 -> 0.27001862 | K21: =K20/K19 -> 0.23913043 | L21: =L20/L19 -> 0.24470135 | M21: =M20/M19 -> 0.2144717 | N21: =N20/N19 -> 0.21985597 | O21: =O20/O19 -> 0.26038961 | P21: =P20/P19 -> 0.26028099
I22: `

Sheet Sensitivity Analysis
A1: Atlassian Sensitivity Analysis
A2: NASDAQ: TEAM
C4: TGR | D4: WACC
D5: =K49 -> 107.76789 | E5: 0.08 | F5: 0.085 | G5: 0.09 | H5: =WACC!H55 -> 0.098174268 | I5: 0.1 | J5: 0.105 | K5: 0.11
D6: 0.02 | E6: 122.02928 | F6: 111.41606 | G6: 102.34399 | H6: 90.058526 | I6: 87.665054 | J6: 81.649436 | K6: 76.319605
D7: 0.025 | E7: 131.63233 | F7: 119.35621 | G7: 108.99516 | H7: 95.154928 | I7: 92.483727 | J7: 85.805879 | K7: 79.931756
D8: 0.03 | E8: 143.156 | F8: 128.74003 | G8: 116.75486 | H8: 100.99888 | I8: 97.990782 | J8: 90.516515 | K8: 83.995425
D9: 0.0325 | E9: 149.8276 | F9: 134.10221 | G9: 121.14078 | H9: 104.25455 | I9: 101.05026 | J9: 93.115486 | K9: 86.223888
D10: ='DCF FINAL'!J44 -> 0.035 | E10: 157.24048 | F10: 140.00061 | G10: 125.92542 | H10: 107.76789 | I10: 104.34508 | J10: 95.900098 | K10: 88.600916
D11: 0.0375 | E11: 165.52547 | F11: 146.51989 | G11: 131.16574 | H11: 111.57076 | I11: 107.90348 | J11: 98.890978 | K11: 91.141877
D12: 0.04 | E12: 174.84608 | F12: 153.76354 | G12: 136.93009 | H12: 115.70048 | I12: 111.75842 | J12: 102.11193 | K12: 93.864335
F18: 43983 | G18: 44377 | H18: =EDATE(G18,12) -> 44742 | I18: =EDATE(H18,12) -> 45107 | J18: =EDATE(I18,12) -> 45473 | K18: =EDATE(J18,12) -> 45838 | L18: =EDATE(K18,12) -> 46203 | M18: =EDATE(L18,12) -> 46568 | N18: =EDATE(M18,12) -> 46934 | O18: =EDATE(N18,12) -> 47299 | ... R18: =EDATE(Q18,12) -> 48395
C19: =Cover!E5 -> Base Case | F19: Actuals | G19: Actuals | H19: Actuals | I19: Actuals | J19: Actuals | K19: Actuals | L19: Actuals | M19: Forecast | N19: Forecast | O19: Forecast | P19: Forecast | Q19: Forecast | R19: Forecast
L20: 0 | M20: 1 | N20: 2 | O20: 3 | P20: 4 | Q20: 5 | R20: 6
C22: Revenue | F22: ='IS Intergrated'!E10 -> 1614.173 | G22: ='DCF FINAL'!E11 -> 2089.132 | H22: ='DCF FINAL'!F11 -> 2802.882 | I22: ='DCF FINAL'!G11 -> 3534.647 | J22: ='DCF FINAL'!H11 -> 4358.603 | K22: ='DCF FINAL'!I11 -> 5215.304 | L22: ='DCF FINAL'!J11 -> 6572.308 | M22: ='DCF FINAL'!K11 -> 7540.3559 | N22: ='DCF FINAL'!L11 -> 9131.9763 | ... R22: ='DCF FINAL'!P11 -> 16156.084
C23: COGS (Excl. D&A) | F23: ='IS Intergrated'!E17 -> 183.628 | G23: ='IS Intergrated'!F17 -> 253.859 | H23: ='IS Intergrated'!G17 -> 410.354 | I23: ='IS Intergrated'!H17 -> 581.285 | J23: ='IS Intergrated'!I17 -> 724.757 | K23: ='IS Intergrated'!J17 -> 816.113 | L23: ='IS Intergrated'!K17 -> 856.162 | M23: ='IS Intergrated'!L17 -> 1194.4376 | ... R23: ='IS Intergrated'!Q17 -> 2963.1227
C24: Gross Profit | F24: ='IS Intergrated'!E22 -> 1345.366 | G24: ='IS Intergrated'!F22 -> 1753.111 | H24: ='IS Intergrated'!G22 -> 2337.175 | I24: ='IS Intergrated'!H22 -> 2900.882 | J24: ='IS Intergrated'!I22 -> 3555.108 | K24: ='IS Intergrated'!J22 -> 4320.453 | L24: ='IS Intergrated'!K22 -> 5575.476 | M24: ='IS Intergrated'!L22 -> 6206.7684 | ... R24: ='IS Intergrated'!Q22 -> 13112.27
C26: EBITDA | F26: ='DCF FINAL'!D17 -> 99.265 | G26: ='DCF FINAL'!E17 -> 183.796 | H26: ='DCF FINAL'!F17 -> -51.104 | I26: ='DCF FINAL'!G17 -> -292.742 | J26: ='DCF FINAL'!H17 -> -38.339 | K26: ='DCF FINAL'!I17 -> -51.654 | L26: ='DCF FINAL'!J17 -> 151.023 | M26: ='DCF FINAL'!K17 -> 188.90568 | ... R26: ='DCF FINAL'!P17 -> 2585.8235
C28: EBIT | F28: ='IS Intergrated'!E29 -> 14.086 | G28: ='IS Intergrated'!F29 -> 101.634 | H28: ='IS Intergrated'!G29 -> -106.457 | I28: ='IS Intergrated'!H29 -> -345.222 | J28: ='IS Intergrated'!I29 -> -117.077 | K28: ='IS Intergrated'!J29 -> -130.392 | L28: ='IS Intergrated'!K29 -> 10.353 | M28: ='IS Intergrated'!L29 -> 49.755724 | ... R28: ='IS Intergrated'!Q29 -> 2505.1327
C30: Net Income | F30: ='IS Intergrated'!E41 -> -350.654 | G30: ='IS Intergrated'!F41 -> -696.315 | H30: ='IS Intergrated'!G41 -> -614.124 | I30: ='IS Intergrated'!H41 -> -486.761 | J30: ='IS Intergrated'!I41 -> -300.519 | K30: ='IS Intergrated'!J41 -> -256.687 | L30: ='IS Intergrated'!K41 -> -53.83 | M30: ='IS Intergrated'!L41 -> 47.013799 | ... R30: ='IS Intergrated'!Q41 -> 2004.8774
C32: Unlevered FCF | F32: ='DCF FINAL'!D31 -> -195.8686 | G32: ='DCF FINAL'!E31 -> -507.23288 | H32: ='DCF FINAL'!F31 -> -399.76124 | I32: ='DCF FINAL'!G31 -> -174.44872 | J32: ='DCF FINAL'!H31 -> 296.19748 | K32: ='DCF FINAL'!I31 -> 18.792 | L32: ='DCF FINAL'!J31 -> -360.801 | M32: ='DCF FINAL'!K31 -> 499.19776 | ... R32: ='DCF FINAL'!P31 -> 2422.7727
C33: PV FCF | M33: =M32/(1+$K$52)^M20 -> 454.57062 | N33: =N32/(1+$K$52)^N20 -> 612.67767 | O33: =O32/(1+$K$52)^O20 -> 765.30508 | P33: =P32/(1+$K$52)^P20 -> 1004.276 | Q33: =Q32/(1+$K$52)^Q20 -> 1182.1386 | R33: =R32/(1+$K$52)^R20 -> 1381.2907
C35: Terminal Value | K35: =R32*(1+K53)/(K52-K53) -> 39692.897
C36: PV of Terminal Value | K36: =K35/(1+K52)^R20 -> 22630.034
C37: PV of FCF | K37: =SUM(L33:R33) -> 5400.2587
C39: Terminal Value SBC | K39: ='DCF FINAL'!J51 -> 14641.236
C40: PV of Terminal Value of SBC | K40: ='DCF FINAL'!J52 -> 8347.3794
C41: Sum of PV of SBC | K41: ='DCF FINAL'!J53 -> 2922.5093
C43: Enterprise Value | K43: =(K36+K37) -> 28030.293
C44: (+) Cash | K44: ='BS Intergrated'!K11 -> 1239.512
C45: (-) Debt | K45: ='DCF FINAL'!J57 -> 1232.91
C46: Equity Value | K46: =K43+K44-K45 -> 28036.895
C47: Number of Shares Outstanding (m) | K47: ='Comp. Multi & Imp. Val'!W13 -> 260.16
C49: Implied Share Price | K49: =K46/K47 -> 107.76789
C50: Current Share Price | K50: ='VWAP LIVE'!I5 -> 178.1217
C52: WACC | K52: =WACC!H55 -> 0.098174268
C53: Terminal Growth Rate | K53: 0.035

Sheet Reverse DCF
B2: Reverse DCF Model | G2: 46174 | H2: 46539 | I2: 46905 | J2: 47270 | K2: 47635 | L2: 48000 | M2: 48366
B3: ($ in millions) | F3: =Cover!E5 -> Base Case | G3: Actuals | H3: Forecast | I3: Forecast | J3: Forecast | K3: Forecast | L3: Forecast | M3: Forecast
G4: 0 | H4: 1 | I4: 2 | J4: 3 | K4: 4 | L4: 5 | M4: 6
B6: Growth Scaling Factor (Goalseek) | G6: 1.6071837
B7: Revenue | G7: ='DCF FINAL'!J11 -> 6572.308 | H7: =G7*(1+H9) -> 8128.1389 | I7: =H7*(1+I9) -> 10885.567 | J7: =I7*(1+J9) -> 14494.072 | K7: =J7*(1+K9) -> 18641.712 | L7: =K7*(1+L9) -> 22546.009 | M7: =L7*(1+M9) -> 26222.384
B8: Base Compound Annual Growth Rate | F8: =_xlfn.RRI('DCF FINAL'!P7,'DCF FINAL'!J11,'DCF FINAL'!P11) -> 0.16172419 | H8: ='DCF FINAL'!K10 -> 0.14729193 | I8: ='DCF FINAL'!L10 -> 0.21108027 | J8: ='DCF FINAL'!M10 -> 0.20625793 | K8: ='DCF FINAL'!N10 -> 0.17805129 | L8: ='DCF FINAL'!O10 -> 0.13031412 | M8: ='DCF FINAL'!P10 -> 0.10145761
B9: Scaled Growth Rate | H9: =H8*$G$6 -> 0.23672519 | I9: =I8*$G$6 -> 0.33924477 | J9: =J8*$G$6 -> 0.33149438 | K9: =K8*$G$6 -> 0.28616114 | L9: =L8*$G$6 -> 0.20943874 | M9: =M8*$G$6 -> 0.16306102
B10: Scaled Compound Annual Growth Rate % | F10: =_xlfn.RRI(M4,G7,M7) -> 0.25938653
B11: EBIT | G11: =G7*G12 -> 10.353 | H11: =H7*H12 -> 53.634263 | I11: =I7*I12 -> 260.64917 | J11: =J7*J12 -> 592.0075 | K11: =K7*K12 -> 1439.8358 | L11: =L7*L12 -> 2666.4099 | M11: =M7*M12 -> 4065.9948
B12: % EBIT Margin | G12: ='IS Intergrated'!K29/'IS Intergrated'!K10 -> 0.0015752457 | H12: ='IS Intergrated'!L29/'IS Intergrated'!L10 -> 0.0065985909 | I12: ='IS Intergrated'!M29/'IS Intergrated'!M10 -> 0.023944473 | J12: ='IS Intergrated'!N29/'IS Intergrated'!N10 -> 0.040844802 | K12: ='IS Intergrated'!O29/'IS Intergrated'!O10 -> 0.077237315 | L12: ='IS Intergrated'!P29/'IS Intergrated'!P10 -> 0.11826527 | M12: ='IS Intergrated'!Q29/'IS Intergrated'!Q10 -> 0.15505817
B13: Non-Operating Income | G13: ='IS Intergrated'!K31 -> 11.695 | H13: ='IS Intergrated'!L31 -> 12.104538 | I13: ='IS Intergrated'!M31 -> 22.941378 | J13: ='IS Intergrated'!N31 -> 35.760401 | K13: ='IS Intergrated'!O31 -> 57.610478 | L13: ='IS Intergrated'!P31 -> 88.971914 | M13: ='IS Intergrated'!Q31 -> 132.86386
B14: Less: Taxes | G14: ='IS Intergrated'!K38 -> 75.878 | H14: =(H11+H13)*WACC!$H$23 -> 15.777312 | I14: =(I11+I13)*WACC!$H$23 -> 68.061732 | J14: =(J11+J13)*WACC!$H$23 -> 150.6643 | K14: =(K11+K13)*WACC!$H$23 -> 359.38711 | L14: =(L11+L13)*WACC!$H$23 -> 661.29164 | M14: =(M11+M13)*WACC!$H$23 -> 1007.7261
B15: Net Income | G15: =G11+G13-G14 -> -53.83 | H15: =H11+H13-H14 -> 49.961489 | I15: =I11+I13-I14 -> 215.52882 | J15: =J11+J13-J14 -> 477.10361 | K15: =K11+K13-K14 -> 1138.0592 | L15: =L11+L13-L14 -> 2094.0902 | M15: =M11+M13-M14 -> 3191.1326
B16: % NI Margin | G16: =G15/G7 -> -0.0081904256 | H16: =H15/H7 -> 0.0061467317 | I16: =I15/I7 -> 0.019799502 | J16: =J15/J7 -> 0.032917155 | K16: =K15/K7 -> 0.061049069 | L16: =L15/L7 -> 0.092880749 | M16: =M15/M7 -> 0.12169498 | P16: =26.37-25.94 -> 0.43 | R16: =25.94-16.17 -> 9.77
B17: (+) D&A | G17: =G18*G7 -> 140.67 | H17: =H18*H7 -> 149.99692 | I17: =I18*I7 -> 175.34633 | J17: =J18*J7 -> 205.92914 | K17: =K18*K7 -> 238.89923 | L17: =L18*L7 -> 153.02756 | M17: =M18*M7 -> 130.96646
B18: % D&A Margin | G18: ='IS Intergrated'!K18/'IS Intergrated'!K10 -> 0.02140344 | H18: ='IS Intergrated'!L18/'IS Intergrated'!L10 -> 0.01845403 | I18: ='IS Intergrated'!M18/'IS Intergrated'!M10 -> 0.016108148 | J18: ='IS Intergrated'!N18/'IS Intergrated'!N10 -> 0.014207818 | K18: ='IS Intergrated'!O18/'IS Intergrated'!O10 -> 0.012815305 | L18: ='IS Intergrated'!P18/'IS Intergrated'!P10 -> 0.006787346 | M18: ='IS Intergrated'!Q18/'IS Intergrated'!Q10 -> 0.0049944528
B19: (-) CapEx | G19: =G20*G7 -> -34.06 | H19: =H20*H7 -> -63.286166 | I19: =I20*I7 -> -75.838234 | J19: =J20*J7 -> -99.0657 | K19: =K20*K7 -> -112.62354 | L19: =L20*L7 -> -103.90213 | M19: =M20*M7 -> -96.549812
B20: % CapEx Margin | G20: ='CF Intergrated'!K30/'IS Intergrated'!K10 -> -0.0051823499 | H20: ='CF Intergrated'!L30/'IS Intergrated'!L10 -> -0.0077860586 | I20: ='CF Intergrated'!M30/'IS Intergrated'!M10 -> -0.0069668608 | J20: ='CF Intergrated'!N30/'IS Intergrated'!N10 -> -0.0068349115 | K20: ='CF Intergrated'!O30/'IS Intergrated'!O10 -> -0.0060414803 | L20: ='CF Intergrated'!P30/'IS Intergrated'!P10 -> -0.0046084487 | M20: ='CF Intergrated'!Q30/'IS Intergrated'!Q10 -> -0.0036819616
B21: (-) Change in NWC | G21: =G22*G7 -> -375.999 | H21: =H22*H7 -> 445.22858 | I21: =I22*I7 -> 611.59859 | J21: =J22*J7 -> 795.40262 | K21: =K22*K7 -> 874.10224 | L21: =L22*L7 -> 786.12255 | M21: =M22*M7 -> 710.86852
B22: % Δ NWC Margin | G22: ='CF Intergrated'!K18/'IS Intergrated'!K10 -> -0.057209583 | H22: ='CF Intergrated'!L18/'IS Intergrated'!L10 -> 0.054776203 | I22: ='CF Intergrated'!M18/'IS Intergrated'!M10 -> 0.056184355 | J22: ='CF Intergrated'!N18/'IS Intergrated'!N10 -> 0.054877789 | K22: ='CF Intergrated'!O18/'IS Intergrated'!O10 -> 0.04688959 | L22: ='CF Intergrated'!P18/'IS Intergrated'!P10 -> 0.034867482 | M22: ='CF Intergrated'!Q18/'IS Intergrated'!Q10 -> 0.027109226
B23: (+) Int Exp | G23: =G24*G7 -> -37.582 | H23: =H24*H7 -> -44.506899 | I23: =I24*I7 -> -49.216913 | J23: =J24*J7 -> -54.326725 | K23: =K24*K7 -> -59.312293 | L23: =L24*L7 -> -63.464291 | M23: =M24*M7 -> -67.013784
B24: % Int. Exp Margin | G24: ='DCF FINAL'!J27/'DCF FINAL'!J11 -> -0.0057182348 | H24: ='DCF FINAL'!K27/'DCF FINAL'!K11 -> -0.0054756568 | I24: ='DCF FINAL'!L27/'DCF FINAL'!L11 -> -0.0045212997 | J24: ='DCF FINAL'!M27/'DCF FINAL'!M11 -> -0.0037482031 | K24: ='DCF FINAL'!N27/'DCF FINAL'!N11 -> -0.0031816977 | L24: ='DCF FINAL'!O27/'DCF FINAL'!O11 -> -0.0028148792 | M24: ='DCF FINAL'!P27/'DCF FINAL'!P11 -> -0.0025555947
B25: (+) Stock Based Compensation | G25: =G26*G7 -> 1606.561 | H25: =H26*H7 -> 1919.4522 | I25: =I26*I7 -> 2516.1885 | J25: =J26*J7 -> 3277.8205 | K25: =K26*K7 -> 4122.5968 | L25: =L26*L7 -> 4873.2982 | M25: =M26*M7 -> 5536.8313
B26: % SBC Margin | G26: ='DCF FINAL'!J28/'DCF FINAL'!J11 -> 0.24444396 | H26: ='DCF FINAL'!K28/'DCF FINAL'!K11 -> 0.23614904 | I26: ='DCF FINAL'!L28/'DCF FINAL'!L11 -> 0.23114904 | J26: ='DCF FINAL'!M28/'DCF FINAL'!M11 -> 0.22614904 | K26: ='DCF FINAL'!N28/'DCF FINAL'!N11 -> 0.22114904 | L26: ='DCF FINAL'!O28/'DCF FINAL'!O11 -> 0.21614904 | M26: ='DCF FINAL'!P28/'DCF FINAL'!P11 -> 0.21114904
B27: (-) Adjustment For SBC | G27: =G28*G7 -> -1185.6894 | H27: =H28*H7 -> -1416.6124 | I27: =I28*I7 -> -1857.0213 | J27: =J28*J7 -> -2419.1282 | K27: =K28*K7 -> -3042.5981 | L27: =L28*L7 -> -3596.6378 | M27: =M28*M7 -> -4086.3448
B28: % SBC Adjustment | G28: ='DCF FINAL'!J29/'DCF FINAL'!J11 -> -0.18040685 | H28: ='DCF FINAL'!K29/'DCF FINAL'!K11 -> -0.17428496 | I28: ='DCF FINAL'!L29/'DCF FINAL'!L11 -> -0.17059481 | J28: ='DCF FINAL'!M29/'DCF FINAL'!M11 -> -0.16690466 | K28: ='DCF FINAL'!N29/'DCF FINAL'!N11 -> -0.16321452 | L28: ='DCF FINAL'!O29/'DCF FINAL'!O11 -> -0.15952437 | M28: ='DCF FINAL'!P29/'DCF FINAL'!P11 -> -0.15583422
B30: Free Cash Flow to Firm (FCFF) | G30: =G15+G17+G19+G21+G23 -> -360.801 | H30: =H15+H17+H19+H21+H23 -> 537.39392 | I30: =I15+I17+I19+I21+I23 -> 877.41859 | J30: =J15+J17+J19+J21+J23 -> 1325.0429 | K30: =K15+K17+K19+K21+K23 -> 2079.1248 | L30: =L15+L17+L19+L21+L23 -> 2865.8739 | M30: =M15+M17+M19+M21+M23 -> 3869.404
B31: Discount Factor (WACC) | F31: =WACC!H8 -> 0.098174268
B32: Present Value of SBC | H32: =(H25+H27)/(1+$F$31)^H4 -> 457.88712 | I32: =(I25+I27)/(1+$F$31)^I4 -> 546.57912 | J32: =(J25+J27)/(1+$F$31)^J4 -> 648.37128 | K32: =(K25+K27)/(1+$F$31)^K4 -> 742.57136 | L32: =(L25+L27)/(1+$F$31)^L4 -> 799.31702 | M32: =(M25+M27)/(1+$F$31)^M4 -> 826.96304
B33: Present Value of FCFF | H33: =H30/(1+$F$31)^H4 -> 489.35213 | I33: =I30/(1+$F$31)^I4 -> 727.55245 | J33: =J30/(1+$F$31)^J4 -> 1000.4979 | K33: =K30/(1+$F$31)^K4 -> 1429.5374 | L33: =L30/(1+$F$31)^L4 -> 1794.3236 | M33: =M30/(1+$F$31)^M4 -> 2206.0558
B37: Implied DCF Valuation | I37: Share Price Calculation
B38: Present Value of FCFFs | G38: =+SUM(H33:M33) -> 7647.3192 | I38: Diluted Shares Outstanding (mm) | L38: ='Comp. Multi & Imp. Val'!W13 -> 260.16
B39: Long-Term Growth Rate | G39: ='DCF FINAL'!J44 -> 0.035 | I39: Implied Share Price | L39: =G51/L38 -> 168.34368
B40: Final Year FCF × (1 + g) | G40: =M30*(1+G39) -> 4004.8331 | I40: Current Market Share Price | L40: ='VWAP LIVE'!I5 -> 178.1217
B41: Terminal Value in Final Year | G41: =G40/(F31-G39) -> 63393.423 | I41: Implied Growth Rate | L41: =F10 -> 0.25938653
B42: Present Value of Terminal Value | G42: =G41/(1+F31)^M4 -> 36142.37
B44: Terminal Value SBC | G44: =((M25+M27)*(1+G39))/(F31-G39) -> 23763.686
B45: PV of Terminal Value of SBC | G45: =G44/(1+F31)^M4 -> 13548.344
B46: Sum of PV of SBC | G46: =SUM(H32:M32) -> 4021.6889
B48: Total Enterprise Value (TEV) | G48: =(G38+G42) -> 43789.689
...

Sheet DuPont Analysis
D5: Year | E5: 2020A | F5: 2021A | G5: 2022A | H5: 2023A | I5: 2024A | J5: 2025A | K5: 2026A | L5: 2027E | M5: 2028E | N5: 2029E | O5: 2030E | P5: 2031E | Q5: 2032E
D6: DuPont Analysis
D7: Gross Margin | E7: ='DCF FINAL'!D13/'DCF FINAL'!D11 -> 0.8862402 | F7: ='DCF FINAL'!E13/'DCF FINAL'!E11 -> 0.8784859 | G7: ='DCF FINAL'!F13/'DCF FINAL'!F11 -> 0.85359569 | H7: ='DCF FINAL'!G13/'DCF FINAL'!G11 -> 0.83554652 | I7: ='DCF FINAL'!H13/'DCF FINAL'!H11 -> 0.83371805 | J7: ='DCF FINAL'!I13/'DCF FINAL'!I11 -> 0.84351574 | K7: ='DCF FINAL'!J13/'DCF FINAL'!J11 -> 0.86973191 | L7: ='DCF FINAL'!K13/'DCF FINAL'!K11 -> 0.841594 | ... Q7: ='DCF FINAL'!P13/'DCF FINAL'!P11 -> 0.816594
D8: EBITDA Margin | E8: ='IS Intergrated'!E55/'IS Intergrated'!E10 -> 0.061495887 | F8: ='IS Intergrated'!F55/'IS Intergrated'!F10 -> 0.087977208 | G8: ='IS Intergrated'!G55/'IS Intergrated'!G10 -> -0.018232662 | H8: ='IS Intergrated'!H55/'IS Intergrated'!H10 -> -0.082820717 | I8: ='IS Intergrated'!I55/'IS Intergrated'!I10 -> -0.008796167 | J8: ='IS Intergrated'!J55/'IS Intergrated'!J10 -> -0.0099043124 | K8: ='IS Intergrated'!K55/'IS Intergrated'!K10 -> 0.022978686 | L8: ='IS Intergrated'!L55/'IS Intergrated'!L10 -> 0.025052621 | ... Q8: ='IS Intergrated'!Q55/'IS Intergrated'!Q10 -> 0.16005262
D9: Net Profit Margin | E9: ='IS Intergrated'!E41/'IS Intergrated'!E10 -> -0.21723446 | F9: ='IS Intergrated'!F41/'IS Intergrated'!F10 -> -0.3333035 | G9: ='IS Intergrated'!G41/'IS Intergrated'!G10 -> -0.21910448 | H9: ='IS Intergrated'!H41/'IS Intergrated'!H10 -> -0.13771135 | I9: ='IS Intergrated'!I41/'IS Intergrated'!I10 -> -0.068948468 | J9: ='IS Intergrated'!J41/'IS Intergrated'!J10 -> -0.049218032 | K9: ='IS Intergrated'!K41/'IS Intergrated'!K10 -> -0.0081904256 | L9: ='IS Intergrated'!L41/'IS Intergrated'!L10 -> 0.0062349576 | ... Q9: ='IS Intergrated'!Q41/'IS Intergrated'!Q10 -> 0.12409427
D10: Asset Turnover | E10: - | F10: ='IS Intergrated'!F10/(('BS Intergrated'!F42+'BS Intergrated'!E42)/2) -> 0.61090947 | G10: ='IS Intergrated'!G10/(('BS Intergrated'!G42+'BS Intergrated'!F42)/2) -> 0.88887966 | H10: ='IS Intergrated'!H10/(('BS Intergrated'!H42+'BS Intergrated'!G42)/2) -> 0.94661204 | I10: ='IS Intergrated'!I10/(('BS Intergrated'!I42+'BS Intergrated'!H42)/2) -> 0.93543073 | J10: ='IS Intergrated'!J10/(('BS Intergrated'!J42+'BS Intergrated'!I42)/2) -> 0.92682713 | K10: ='IS Intergrated'!K10/(('BS Intergrated'!K42+'BS Intergrated'!J42)/2) -> 1.0822623 | L10: ='IS Intergrated'!L10/(('BS Intergrated'!L42+'BS Intergrated'!K42)/2) -> 1.1966916 | M10: ='IS Intergrated'!M10/(('BS Intergrated'!M42+'BS Intergrated'!L42)/2) -> 1.3016542 | ... Q10: ='IS Intergrated'!Q10/(('BS Intergrated'!Q42+'BS Intergrated'!P42)/2) -> 1.1295075
D11: Return on Assets | E11: - | F11: ='IS Intergrated'!F41/(('BS Intergrated'!F42+'BS Intergrated'!E42)/2) -> -0.20361826 | G11: ='IS Intergrated'!G41/(('BS Intergrated'!G42+'BS Intergrated'!F42)/2) -> -0.19475751 | H11: ='IS Intergrated'!H41/(('BS Intergrated'!H42+'BS Intergrated'!G42)/2) -> -0.13035922 | I11: ='IS Intergrated'!I41/(('BS Intergrated'!I42+'BS Intergrated'!H42)/2) -> -0.064496516 | J11: ='IS Intergrated'!J41/(('BS Intergrated'!J42+'BS Intergrated'!I42)/2) -> -0.045616608 | K11: ='IS Intergrated'!K41/(('BS Intergrated'!K42+'BS Intergrated'!J42)/2) -> -0.0088641891 | L11: ='IS Intergrated'!L41/(('BS Intergrated'!L42+'BS Intergrated'!K42)/2) -> 0.0074613212 | M11: ='IS Intergrated'!M41/(('BS Intergrated'!M42+'BS Intergrated'!L42)/2) -> 0.026172456 | ... Q11: ='IS Intergrated'!Q41/(('BS Intergrated'!Q42+'BS Intergrated'!P42)/2) -> 0.14016541
D12: Financial Leverage (A/E) | E12: - | F12: =(AVERAGE('BS Intergrated'!E42:F42)/AVERAGE('BS Intergrated'!E72:F72)) -> 7.8594103 | G12: =(AVERAGE('BS Intergrated'!F42:G42)/AVERAGE('BS Intergrated'!F72:G72)) -> 10.002189 | H12: =(AVERAGE('BS Intergrated'!G42:H42)/AVERAGE('BS Intergrated'!G72:H72)) -> 7.5412583 | I12: =(AVERAGE('BS Intergrated'!H42:I42)/AVERAGE('BS Intergrated'!H72:I72)) -> 5.5222162 | J12: =(AVERAGE('BS Intergrated'!I42:J42)/AVERAGE('BS Intergrated'!I72:J72)) -> 4.7315928 | K12: =(AVERAGE('BS Intergrated'!J42:K42)/AVERAGE('BS Intergrated'!J72:K72)) -> 5.0520151 | L12: =(AVERAGE('BS Intergrated'!K42:L42)/AVERAGE('BS Intergrated'!K72:L72)) -> 5.823768 | M12: =(AVERAGE('BS Intergrated'!L42:M42)/AVERAGE('BS Intergrated'!L72:M72)) -> 5.8597645 | ... Q12: =(AVERAGE('BS Intergrated'!P42:Q42)/AVERAGE('BS Intergrated'!P72:Q72)) -> 2.9478971
D13: Return on Equity | E13: - | F13: ='IS Intergrated'!F41/(AVERAGE('BS Intergrated'!E72:F72)) -> -1.6003195 | G13: ='IS Intergrated'!G41/(AVERAGE('BS Intergrated'!F72:G72)) -> -1.9480014 | H13: ='IS Intergrated'!H41/(AVERAGE('BS Intergrated'!G72:H72)) -> -0.98307255 | I13: ='IS Intergrated'!I41/(AVERAGE('BS Intergrated'!H72:I72)) -> -0.3561637 | J13: ='IS Intergrated'!J41/(AVERAGE('BS Intergrated'!I72:J72)) -> -0.21583921 | K13: ='IS Intergrated'!K41/(AVERAGE('BS Intergrated'!J72:K72)) -> -0.044782017 | L13: ='IS Intergrated'!L41/(AVERAGE('BS Intergrated'!K72:L72)) -> 0.043453004 | M13: ='IS Intergrated'!M41/(AVERAGE('BS Intergrated'!L72:M72)) -> 0.15336443 | ... Q13: ='IS Intergrated'!Q41/(AVERAGE('BS Intergrated'!P72:Q72)) -> 0.41319322 | U13: Weight (%) | V13: Value
D14: Rule of 40 | E14: - | F14: =('DCF FINAL'!E11/'DCF FINAL'!D11-1)+('CF Intergrated'!F53/'DCF FINAL'!E11) -> 0.62375921 | G14: =('DCF FINAL'!F11/'DCF FINAL'!E11-1)+('CF Intergrated'!G53/'DCF FINAL'!F11) -> 0.57420577 | H14: =('DCF FINAL'!G11/'DCF FINAL'!F11-1)+('CF Intergrated'!H53/'DCF FINAL'!G11) -> 0.49937383 | I14: =('DCF FINAL'!H11/'DCF FINAL'!G11-1)+('CF Intergrated'!I53/'DCF FINAL'!H11) -> 0.55776451 | J14: =('DCF FINAL'!I11/'DCF FINAL'!H11-1)+('CF Intergrated'!J53/'DCF FINAL'!I11) -> 0.46797503 | K14: =('DCF FINAL'!J11/'DCF FINAL'!I11-1)+('CF Intergrated'!K53/'DCF FINAL'!J11) -> 0.46089756 | L14: =('DCF FINAL'!K11/'DCF FINAL'!J11-1)+('CF Intergrated'!L53/'DCF FINAL'!K11) -> 0.4551201 | M14: =('DCF FINAL'!L11/'DCF FINAL'!K11-1)+('CF Intergrated'!M53/'DCF FINAL'!L11) -> 0.52766202 | ... Q14: =('DCF FINAL'!P11/'DCF FINAL'!O11-1)+('CF Intergrated'!Q53/'DCF FINAL'!P11) -> 0.46512264 | T14: DCF Valuation | U14: 1 | V14: ='DCF FINAL'!J61 -> 107.76789
D15: Liquidity | T15: Comparables Valuation | U15: 0 | V15: =83.6 -> 83.6
D16: Current Ratio | E16: ='BS Intergrated'!E18/'BS Intergrated'!E54 -> 0.87577991 | F16: ='BS Intergrated'!F18/'BS Intergrated'!F54 -> 0.7045447 | G16: ='BS Intergrated'!G18/'BS Intergrated'!G54 -> 1.19146 | H16: ='BS Intergrated'!H18/'BS Intergrated'!H54 -> 1.3495648 | I16: ='BS Intergrated'!I18/'BS Intergrated'!I54 -> 1.1785883 | J16: ='BS Intergrated'!J18/'BS Intergrated'!J54 -> 1.2233278 | K16: ='BS Intergrated'!K18/'BS Intergrated'!K54 -> 0.78325942 | L16: ='BS Intergrated'!L18/'BS Intergrated'!L54 -> 0.72580308 | ... Q16: ='BS Intergrated'!Q18/'BS Intergrated'!Q54 -> 0.74253799 | T16: Target Price | U16: - | V16: 108.26452
D17: Quick Ratio | E17: =('BS Intergrated'!E11+'BS Intergrated'!E12+'BS Intergrated'!E13)/'BS Intergrated'!E54 -> 0.75131701 | F17: =('BS Intergrated'!F11+'BS Intergrated'!F12+'BS Intergrated'!F13)/'BS Intergrated'!F54 -> 0.60852567 | G17: =('BS Intergrated'!G11+'BS Intergrated'!G12+'BS Intergrated'!G13)/'BS Intergrated'!G54 -> 1.1082961 | H17: =('BS Intergrated'!H11+'BS Intergrated'!H12+'BS Intergrated'!H13)/'BS Intergrated'!H54 -> 1.277491 | I17: =('BS Intergrated'!I11+'BS Intergrated'!I12+'BS Intergrated'!I13)/'BS Intergrated'!I54 -> 1.1367083 | J17: =('BS Intergrated'!J11+'BS Intergrated'!J12+'BS Intergrated'!J13)/'BS Intergrated'!J54 -> 1.168062 | K17: =('BS Intergrated'!K11+'BS Intergrated'!K12+'BS Intergrated'!K13)/'BS Intergrated'!K54 -> 0.70270707 | L17: =('BS Intergrated'!L11+'BS Intergrated'!L12+'BS Intergrated'!L13)/'BS Intergrated'!L54 -> 0.63779783 | ... Q17: =('BS Intergrated'!Q11+'BS Intergrated'!Q12+'BS Intergrated'!Q13)/'BS Intergrated'!Q54 -> 0.6684718 | T17: Implied Downside | U17: - | V17: -0.36850966
D18: Debt Ratio
D19: Interest Coverage Ratio | E19: =-('IS Intergrated'!E29/'IS Intergrated'!E34) -> 0.28393469 | F19: =-('IS Intergrated'!F29/'IS Intergrated'!F34) -> 0.82822521 | G19: =-('IS Intergrated'!G29/'IS Intergrated'!G34) -> -4.1224055 | H19: =-('IS Intergrated'!H29/'IS Intergrated'!H34) -> -11.451289 | I19: =-('IS Intergrated'!I29/'IS Intergrated'!I34) -> -3.4356604 | J19: =-('IS Intergrated'!J29/'IS Intergrated'!J34) -> -4.2681506 | K19: =-('IS Intergrated'!K29/'IS Intergrated'!K34) -> 0.20936299 | L19: =-('IS Intergrated'!L29/'IS Intergrated'!L34) -> 0.91585891 | ... Q19: =-('IS Intergrated'!Q29/'IS Intergrated'!Q34) -> 46.112245
D20: Debt/EBITDA | E20: =('BS Intergrated'!E59+'BS Intergrated'!E48)/'IS Intergrated'!E55 -> 2.5125472 | F20: =('BS Intergrated'!F59+'BS Intergrated'!F48)/'IS Intergrated'!F55 -> 1.3936865 | G20: =('BS Intergrated'!G59+'BS Intergrated'!G48)/'IS Intergrated'!G55 -> -5.8860559 | H20: =('BS Intergrated'!H59+'BS Intergrated'!H48)/'IS Intergrated'!H55 -> -0.81243894 | I20: =('BS Intergrated'!I59+'BS Intergrated'!I48)/'IS Intergrated'!I55 -> -5.594147 | J20: =('BS Intergrated'!J59+'BS Intergrated'!J48)/'IS Intergrated'!J55 -> -3.9006273 | K20: =('BS Intergrated'!K59+'BS Intergrated'!K48)/'IS Intergrated'!K55 -> 1.2901412 | L20: =('BS Intergrated'!L59+'BS Intergrated'!L48)/'IS Intergrated'!L55 -> 1.0314195 | ... Q20: =('BS Intergrated'!Q59+'BS Intergrated'!Q48)/'IS Intergrated'!Q55 -> 0.075349689
T26: 1-Month VWAP | U26: ='VWAP LIVE'!I7 -> 0
T27: Market Cap | U27: $48.833B
T28: Shares Outstanding | U28: 260.16M
T29: 52-Week High | U29: 198.6
T30: 52-Week Low | U30: 56.01

Sheet Altman's Z-Score
A1: Altman's Z-Score
C4: Parameters - Actuals | F4: Calculations
C5: Income statement | H5: Variable | I5: Factor
C6: Net sales | D6: ='DCF FINAL'!J11 -> 6572.308 | F6: Working Cap / Total Assets | H6: =(D10-D12)/D11 -> -0.12681336 | I6: 1.2
C7: Operating income | D7: ='DCF FINAL'!J19 -> 10.353 | F7: Retained Earnings / Total Assets | H7: =D14/D11 -> -1.0003029 | I7: 1.4
F8: EBIT / Total Assets | H8: =D7/D11 -> 0.0016962318 | I8: 3.3
C9: Balance sheet | F9: Net Sales / Total Assets | H9: =D6/D11 -> 1.0768046 | I9: 1
C10: Current assets | D10: ='BS Intergrated'!K18 -> 2797.122 | F10: Market value of equity/Total liabilities | H10: =D16/D13 -> 9.1851964 | I10: 0.6
C11: Total assets | D11: ='BS Intergrated'!K42 -> 6103.529
C12: Current liabilities | D12: ='BS Intergrated'!K54 -> 3571.131 | F12: Z Score | G12: =SUMPRODUCT(H6:H10,I6:I10) -> 5.0409199
C13: Total liabilities | D13: ='BS Intergrated'!K65 -> 5045.09
C14: Retained earnings | D14: ='BS Intergrated'!K70 -> -6105.378
F15: Key
C16: Market value of equity | D16: ='Comp. Multi & Imp. Val'!W9 -> 46340.143 | F16: Z < 1.81 | G16: Bad
C17: Book value of equity | D17: =D11-D13 -> 1058.439 | F17: 1.81 < Z < 2.99 | G17: Moderate
F18: Z > 2.99 | G18: Excellent

Sheet Chaffe-Finnerty DLOM
A1: Chaffe & Finntery Discount for Lack of Marketability
A2: 409A Valuation(s)
A3: NASDAQ:TEAM
B6: TEAM RSU Vesting Schedule | F6: ICAEW Presentation | I6: Finnerty Paper | L6: Precendent(s) | M6: Stout | N6: Precedent 2
B7: 1 | C7: 0.25 | F7: Chaffe Model | I7: Finnerty Model
B8: 2 | C8: 0.25 | F8: Sigma Annualized | G8: =_xlfn.STDEV.S(C15:C540)*SQRT(52) -> 0.50953948 | I8: Sigma Annualized | J8: =_xlfn.STDEV.S(C15:C540)*SQRT(52) -> 0.50953948
B9: 3 | C9: 0.25 | F9: Vesting | G9: =SUMPRODUCT(B7:B10,C7:C10)/SUM(C7:C10) -> 2.5 | I9: q | J9: 0 | K9: No div
B10: 4 | C10: 0.25 | F10: rf | G10: ='DCS Detail'!D5 -> 0.04975 | I10: L (vesting) | J10: =SUMPRODUCT(B7:B10,C7:C10)/SUM(C7:C10) -> 2.5
F11: S | G11: ='VWAP LIVE'!I5 -> 178.1217 | I11: v | J11: =SQRT(J8^2+LN(2*(EXP(J8^2)-J8^2-1))-2*LN(EXP(J8^2)-1)) -> 0.28778985 | K11: Effective volatility, equation 6
F12: K | G12: =G11 -> 178.1217 | I12: p | J12: =_xlfn.NORM.S.DIST(J11/2,TRUE) - _xlfn.NORM.S.DIST(-J11/2,TRUE) -> 0.11441656 | K12: 1y marketability discount, equation 7
B13: Date | C13: TEAM Weekly Returns 10 yr (%) | F13: d1 | G13: =(LN(G11/G12)+(G10+G8^2/2)*G9)/(G8*SQRT(G9)) -> 0.55720427 | I13: Delta | J13: =-LN(1-J12) -> 0.12150859 | K13: Annualised decay rate, equation 8
B14: 42552 | F14: d2 | G14: =G13-(G8*SQRT(G9)) -> -0.24844839 | I14: Delta * | J14: =1-EXP(-J13*J10) -> 0.2619705 | K14: Multi-year discount, equation 9/10
B15: 42559 | C15: 0.053083528 | F15: P | G15: =G12*EXP(-G10*G9)*_xlfn.NORM.S.DIST(-G14,TRUE)-G11*_xlfn.NORM.S.DIST(-G13,TRUE) -> 42.653553 | I15: Adjustment (α) | J15: =1-J14 -> 0.7380295
B16: 42566 | C16: 0.015567087 | F16: Discount | G16: =G15/G11 -> 0.23946297
B17: 42573 | C17: 0.027737226 | F17: Adjustment (α) | G17: =1-G16 -> 0.76053703
B18: 42580 | C18: 0.064275568
B19: 42587 | C19: 0.0667334
B20: 42594 | C20: -0.061620269
B21: 42601 | C21: -0.019333333
B22: 42608 | C22: -0.016315432
B23: 42615 | C23: 0.04008293
B24: 42622 | C24: -0.020598007
B25: 42629 | C25: 0.017639077
B26: 42636 | C26: 0.025
B27: 42643 | C27: -0.025365854
B28: 42650 | C28: -0.05672339
B29: 42657 | C29: 0.0053059781
... B540: 46234 | C540: 0.16269567

Sheet VWAP LIVE
A1: Trailing Monthly VWAP
B2: #VALUE!
B5: Date | C5: High | D5: Low | E5: Close | F5: Volume | H5: 31-Day Trailing VWAP | I5: {=_xlfn.LET(_xlpm.d,_xlfn.ANCHORARRAY(B6),_xlpm.tp,(INDEX(_xlpm.d,,2)+INDEX(_xlpm.d,,3)+INDEX(_xlpm.d,,4))/3,_xlpm.v,INDEX(_xlpm.d,,5),IF(SUM(_xlpm.v)=0,NA(),SUMPRODUCT(_xlpm.tp,_xlpm.v)/SUM(_xlpm.v)))} -> 178.1217
B6: {=_xlfn.STOCKHISTORY($B$2,TODAY()-31,TODAY(),0,0,0,3,4,1,5)} -> 46251 | C6: 161.6 | D6: 156.5501 | E6: 158.34 | F6: 3048946
B7: 46252 | C7: 167.87 | D7: 158.58 | E7: 163 | F7: 4888443 | H7: 31-Day Trailing VWAP
B8: 46253 | C8: 176.15 | D8: 161.5 | E8: 174.23 | F8: 6066916
B9: 46254 | C9: 177.88 | D9: 171.22 | E9: 174.91 | F9: 5458362
B10: 46255 | C10: 176 | D10: 168.01 | E10: 171.81 | F10: 3275677
B11: 46258 | C11: 174.2341 | D11: 169.04 | E11: 171.33 | F11: 2584312
B12: 46259 | C12: 172.1 | D12: 165.1 | E12: 166.49 | F12: 2909953
B13: 46260 | C13: 170 | D13: 160.962 | E13: 168.47 | F13: 4127538
B14: 46261 | C14: 185.73 | D14: 168.73 | E14: 185.62 | F14: 6073950
B15: 46262 | C15: 194.96 | D15: 185 | E15: 190.415 | F15: 5224708
B16: 46265 | C16: 197.3 | D16: 187.67 | E16: 194.17 | F16: 5117290
B17: 46266 | C17: 193.645 | D17: 185.45 | E17: 187.03 | F17: 3891792
B18: 46267 | C18: 192.87 | D18: 184.73 | E18: 186.44 | F18: 3546782
B19: 46268 | C19: 198.5999 | D19: 190.61 | E19: 194.68 | F19: 3359288
B20: 46269 | C20: 193.425 | D20: 186.54 | E20: 189.58 | F20: 2473769

Sheet Charts
Z1: Increases YoY
J2: '20A | K2: '21A | L2: '22A | M2: '23A | N2: '24A | O2: '25A | P2: '26A | Q2: '27E | R2: '28E | S2: '29E | T2: '30E | U2: '31E | V2: '32E | AA2: '20A | AB2: '21A | AC2: '22A | AD2: '23A | AE2: '24A | AF2: '25A | AG2: '26A
C3: Figure XX: Goodwill by Fiscal Year (US$m) - Investment Summary | J3: ='IS Intergrated'!E25/'IS Intergrated'!E$10 -> 0.47280434 | K3: ='IS Intergrated'!F25/'IS Intergrated'!F$10 -> 0.46111304 | L3: ='IS Intergrated'!G25/'IS Intergrated'!G$10 -> 0.49861821 | M3: ='IS Intergrated'!H25/'IS Intergrated'!H$10 -> 0.52901492 | N3: ='IS Intergrated'!I25/'IS Intergrated'!I$10 -> 0.50110345 | O3: ='IS Intergrated'!J25/'IS Intergrated'!J$10 -> 0.5118229 | P3: ='IS Intergrated'!K25/'IS Intergrated'!K$10 -> 0.49742906 | Q3: ='IS Intergrated'!L25/'IS Intergrated'!L$10 -> 0.46260265 | ... V3: ='IS Intergrated'!Q25/'IS Intergrated'!Q$10 -> 0.33760265 | AA3: 25.4 | AB3: =31.3+AA3 -> 56.7 | AC3: =35+AB3 -> 91.7 | AD3: =56.1+AC3 -> 147.8 | AE3: =101.9+AD3 -> 249.7 | AF3: =32.5+AE3 -> 282.2 | AG3: =87+AF3 -> 369.2
A4: '20A | B4: 645.14 | C4: =B4/608.907-1 -> 0.059504982 | J4: ='IS Intergrated'!E26/'IS Intergrated'!E$10 -> 0.1856573 | K4: ='IS Intergrated'!F26/'IS Intergrated'!F$10 -> 0.17849949 | L4: ='IS Intergrated'!G26/'IS Intergrated'!G$10 -> 0.20253832 | M4: ='IS Intergrated'!H26/'IS Intergrated'!H$10 -> 0.21780421 | N4: ='IS Intergrated'!I26/'IS Intergrated'!I$10 -> 0.20132529 | O4: ='IS Intergrated'!J26/'IS Intergrated'!J$10 -> 0.21753957 | P4: ='IS Intergrated'!K26/'IS Intergrated'!K$10 -> 0.23449571 | Q4: ='IS Intergrated'!L26/'IS Intergrated'!L$10 -> 0.23449571 | ... V4: ='IS Intergrated'!Q26/'IS Intergrated'!Q$10 -> 0.22449571 | AB4: =(AB3-AA3)/AA3 -> 1.2322835 | AC4: =(AC3-AB3)/AB3 -> 0.61728395 | AD4: =(AD3-AC3)/AC3 -> 0.61177754 | AE4: =(AE3-AD3)/AD3 -> 0.6894452 | AF4: =(AF3-AE3)/AE3 -> 0.13015619 | AG4: =(AG3-AF3)/AF3 -> 0.30829199
A5: '21A | B5: 725.758 | C5: =B5/B4-1 -> 0.12496202 | J5: ='IS Intergrated'!E27/'IS Intergrated'!E$10 -> 0.16628267 | K5: ='IS Intergrated'!F27/'IS Intergrated'!F$10 -> 0.15089616 | L5: ='IS Intergrated'!G27/'IS Intergrated'!G$10 -> 0.17067183 | M5: ='IS Intergrated'!H27/'IS Intergrated'!H$10 -> 0.17154811 | N5: ='IS Intergrated'!I27/'IS Intergrated'!I$10 -> 0.14008548 | O5: ='IS Intergrated'!J27/'IS Intergrated'!J$10 -> 0.12405758 | P5: ='IS Intergrated'!K27/'IS Intergrated'!K$10 -> 0.11482846 | Q5: ='IS Intergrated'!L27/'IS Intergrated'!L$10 -> 0.11944302 | ... V5: ='IS Intergrated'!Q27/'IS Intergrated'!Q$10 -> 0.09444302
A6: '22A | B6: 732.666 | C6: =B6/B5-1 -> 0.0095183243 | AA6: Figure XX: Inference Costs by Fiscal Year (US$m)
A7: '23A | B7: 727.221 | C7: =B7/B6-1 -> -0.0074317629 | J7: Figure XX: R&D, M&S, G&A Margins by Fiscal Year (%) - Investment Summary
